<?xml version="1.0" encoding="utf-8"?>
<!-- This URDF was automatically created by SolidWorks to URDF Exporter! Originally created by Stephen Brawner (brawner@gmail.com) 
     Commit Version: 1.6.0-4-g7f85cfe  Build Version: 1.6.7995.38578
     For more information, please see http://wiki.ros.org/sw_urdf_exporter -->
<robot
  name="t1">

    <gazebo>
    <plugin name="gazebo_ros_control" filename="liblegged_hw_sim.so">
      <robotNamespace>/</robotNamespace>
      <robotParam>legged_robot_description</robotParam>
      <robotSimType>legged_gazebo/LeggedHWSim</robotSimType>
    </plugin>
  </gazebo>


  <gazebo>
    <plugin filename="libgazebo_ros_p3d.so" name="p3d_base_controller">
      <alwaysOn>true</alwaysOn>
      <updateRate>500.0</updateRate>
      <bodyName>base_link</bodyName>
      <topicName>ground_truth/state</topicName>
      <gaussianNoise>0</gaussianNoise>
      <frameName>world</frameName>
      <xyzOffsets>0 0 0</xyzOffsets>
      <rpyOffsets>0 0 0</rpyOffsets>
    </plugin>
  </gazebo>

  <link
    name="base_link">
    <inertial>
      <origin
        xyz="0.073 0 0.039"
        rpy="0 0 0" />
      <mass
        value="4.999" />
      <inertia
        ixx="0.039"
        ixy="9.53219619778216E-07"
        ixz="-0.002"
        iyy="0.011"
        iyz="5.223135412837E-08"
        izz="0.046" />
    </inertial>
    <visual>
      <origin
        xyz="0 0 0"
        rpy="0 0 0" />
      <geometry>
        <mesh
          filename="package://legged_ti5_description/meshes/PELVIS_S.STL" />
      </geometry>
      <material
        name="">
        <color
          rgba="0.898039215686275 0.917647058823529 0.929411764705882 1" />
      </material>
    </visual>
    <collision>
      <origin
        xyz="0 0 0"
        rpy="0 0 0" />
      <geometry>
        <mesh
          filename="package://legged_ti5_description/meshes/PELVIS_S.STL" />
      </geometry>
    </collision>
  </link>

  <joint name="base_imu_joint" type="fixed">
    <origin rpy="0. 0. 0." xyz="0. 0. 0" />
    <parent link="base_link" />
    <child link="base_imu" />
  </joint>
  <!-- Imu link -->
  <link name="base_imu">
    <inertial>
      <mass value="0.01" />
      <origin rpy="0 0 0" xyz="0 0 0" />
      <inertia ixx="0.000001" ixy="0" ixz="0" iyy="0.000001" iyz="0" izz="0.000001" />
    </inertial>
    <visual>
      <origin rpy="0 0 0" xyz="0 0 0" />
      <geometry>
        <box size="0.015 0.015 0.004" />
      </geometry>
    </visual>
    <material name="orange">
      <color rgba="255 108 10 255" />
    </material>
  </link>
  <gazebo reference="base_imu_joint">
    <disableFixedJointLumping>true</disableFixedJointLumping>
  </gazebo>
  <!-- ************************************************************ -->
  <!-- ************************ Left Leg ************************** -->
  <!-- ************************************************************ -->
    
    <!-- ************* part 1 *************** -->
  <link
    name="leg_l1_link">
    <inertial>
      <origin
        xyz="-0.088 0 -0.077"
        rpy="0 0 0" />
      <mass
          value="1.679" />
      <inertia
         ixx="0.002"
        ixy="0.00"
        ixz="0.001"
        iyy="0.003"
        iyz="0.000"
        izz="0.002" />
    </inertial>
    <visual>
      <origin
        xyz="0 0 0"
        rpy="0 0 0" />
      <geometry>
        <mesh
          filename="package://legged_ti5_description/meshes/L_HIP_Y_S.STL" />
      </geometry>
      <material
        name="">
        <color
          rgba="0.898039215686275 0.917647058823529 0.929411764705882 1" />
      </material>
    </visual>
    <!-- <collision>
      <origin
        xyz="0 0 0"
        rpy="0 0 0" />
      <geometry>
        <mesh
          filename="package://legged_ti5_description/meshes/L_HIP_Y_S.STL" />
      </geometry>
    </collision> -->
  </link>
  <joint
    name="leg_l1_joint"
    type="revolute">
    <origin
      xyz="0.1067 0.105 0.0005"
      rpy="0 0 0" />
    <parent
      link="base_link" />
    <child
      link="leg_l1_link" />
    <axis
      xyz="0 0 1" />
    <dynamics damping="0.0" friction="0.00" />
    <limit
      lower="-0.523"
      upper="0.523"
      effort="300"
      velocity="41.88790205" />
    <dynamics
      friction="0" />
  </joint>
  <link
    name="leg_l2_link">
    <inertial>
      <origin
       xyz="0.071 0.009 0.000"
        rpy="0 0 0" />
      <mass
        value="3.287" />
      <inertia
        ixx="0.006"
        ixy="0.000"
        ixz="0.000"
        iyy="0.006"
        iyz="0.000"
        izz="0.006" />
    </inertial>
    <visual>
      <origin
        xyz="0 0 0"
        rpy="0 0 0" />
      <geometry>
        <mesh
          filename="package://legged_ti5_description/meshes/L_HIP_R_S.STL" />
      </geometry>
      <material
        name="">
        <color
          rgba="0.898039215686275 0.917647058823529 0.929411764705882 1" />
      </material>
    </visual>
    <!-- <collision>
      <origin
        xyz="0 0 0"
        rpy="0 0 0" />
      <geometry>
        <mesh
          filename="package://legged_ti5_description/meshes/L_HIP_R_S.STL" />
      </geometry>
    </collision> -->
  </link>
  <joint
    name="leg_l2_joint"
    type="revolute">
    <origin
      xyz="-0.074 0 -0.0905"
      rpy="0 0 0" />
    <parent
      link="leg_l1_link" />
    <child
      link="leg_l2_link" />
    <axis
      xyz="1 0 0" />
    <limit
      lower="-0.174"
      upper="0.174"
      effort="300"
      velocity="41.88790205" />
    <dynamics damping="0.0" friction="0.00" />
  </joint>
  <link
    name="leg_l3_link">
    <inertial>
      <origin
        xyz="0.005 0.053 -0.178"
        rpy="0 0 0" />
      <mass
        value="6.432" />
      <inertia
        ixx="0.054"
        ixy="0.000"
        ixz="-0.001"
        iyy="0.056"
        iyz="0.002"
        izz="0.011" />
    </inertial>
    <visual>
      <origin
        xyz="0 0 0"
        rpy="0 0 0" />
      <geometry>
        <mesh
          filename="package://legged_ti5_description/meshes/L_HIP_P_S.STL" />
      </geometry>
      <material
        name="">
        <color
          rgba="0.898039215686275 0.917647058823529 0.929411764705882 1" />
      </material>
    </visual>
    <!-- <collision>
      <origin
       xyz="0.01 0.06 -0.185"
        rpy="0 0 0" />
      <geometry>
        <box size="0.12 0.12 0.30" />
        <mesh
          filename="package://legged_ti5_description/meshes/L_HIP_P_S.STL" />
      </geometry>
    </collision> -->
  </link>
  <joint
    name="leg_l3_joint"
    type="revolute">
    <origin
      xyz="0.074 -0.0255 0"
      rpy="0 0 0" />
    <parent
      link="leg_l2_link" />
    <child
      link="leg_l3_link" />
    <axis
      xyz="0 1 0" />
    <limit
      lower="-0.785"
      upper="0.785"
      effort="300"
      velocity="57.59586532" />
    <dynamics damping="0.0" friction="0.00" />
  </joint>
  <link
    name="leg_l4_link">
    <inertial>
      <origin
        xyz="-0.001 0.056 -0.168"
        rpy="0 0 0" />
      <mass
        value="3.222" />
      <inertia
        ixx="0.031"
        ixy="0.000"
        ixz="0.000"
        iyy="0.03"
        iyz="-0.002"
        izz="0.002" />
    </inertial>
    <visual>
      <origin
        xyz="0 0 0"
        rpy="0 0 0" />
      <geometry>
        <mesh
          filename="package://legged_ti5_description/meshes/L_KNEE_P_S.STL" />
      </geometry>
      <material
        name="">
        <color
          rgba="0.898039215686275 0.917647058823529 0.929411764705882 1" />
      </material>
    </visual>
    <!-- <collision>
      <origin
        xyz="0 0.05 -0.11"
        rpy="0 0 0" />
      <geometry>
        <box size="0.1 0.1 0.30" />
        <mesh
          filename="package://legged_ti5_description/meshes/L_KNEE_P_S.STL" />
      </geometry>
    </collision> -->
  </link>
  <joint
    name="leg_l4_joint"
    type="revolute">
    <origin
      xyz="0 -0.0226 -0.42"
      rpy="0 0 0" />
    <parent
      link="leg_l3_link" />
    <child
      link="leg_l4_link" />
    <axis
      xyz="0 1 0" />
    <limit
      lower="0"
      upper="2.09"
      effort="300"
      velocity="57.59586532" />
    <dynamics damping="0.0" friction="0.00" />
  </joint>
  <link
    name="leg_l5_link">
    <inertial>
      <origin
        xyz="0.002 -0.046 0.0000"
        rpy="0 0 0" />
      <mass
        value="0.629" />
      <inertia
        ixx="0.00023285"
        ixy="0"
        ixz="0"
        iyy="0.00029849"
        iyz="0"
        izz="0.00028791" />
    </inertial>
    <visual>
      <origin
        xyz="0 0 0"
        rpy="0 0 0" />
      <geometry>
        <mesh
          filename="package://legged_ti5_description/meshes/L_ANKLE_P_S.STL" />
      </geometry>
      <material
        name="">
        <color
          rgba="0.647058823529412 0.619607843137255 0.588235294117647 1" />
      </material>
    </visual>
    <!-- <collision>
      <origin
        xyz="0 0 0"
        rpy="0 0 0" />
      <geometry>
        <mesh
          filename="package://legged_ti5_description/meshes/L_ANKLE_P_S.STL" />
      </geometry>
    </collision> -->
  </link>
  <joint
    name="leg_l5_joint"
    type="revolute">
    <origin
      xyz="0 0.0936 -0.37"
      rpy="0 0 0" />
    <parent
      link="leg_l4_link" />
    <child
      link="leg_l5_link" />
    <axis
      xyz="0 1 0" />  
    <limit
      lower="-2"
      upper="2" 
      effort="300"
      velocity="85.8701992" />
    <dynamics damping="0.0" friction="0.00" />
  </joint>
  <link
    name="leg_l6_link">
    <inertial>
      <origin
        xyz="0.003 -0.002 -0.068"
        rpy="0 0 0" />
      <mass
        value="0.802" />
      <inertia
        ixx="0.001"
        ixy="0"
        ixz="0"
        iyy="0.003"
        iyz="0"
        izz="0.003" />
    </inertial>
    <visual>
      <origin
        xyz="0 0 0"
        rpy="0 0 0" />
      <geometry>
        <mesh
          filename="package://legged_ti5_description/meshes/L_ANKLE_R_S.STL" />
      </geometry>
      <material
        name="">
        <color
          rgba="1 1 1 1" />
      </material>
    </visual>
    <collision>    
    <!-- <origin
        xyz="-0.0 -0.00  -0.0715"
        rpy="0 0 0" /> -->
      <origin
        xyz="-0.0 -0.00  0.0"
        rpy="0 0 0" />
      <geometry>
        <mesh
          filename="package://legged_ti5_description/meshes/L_ANKLE_R_S.STL" />
         </geometry>
      <!-- <geometry>
        <box size="0.215 0.084 0.017" />
      </geometry> -->
    </collision>
  </link>
  <joint
    name="leg_l6_joint"
    type="revolute">
    <origin
      xyz="0.02595 -0.049 0"
      rpy="0 0 0" />
    <parent
      link="leg_l5_link" />
    <child
      link="leg_l6_link" />
    <axis
      xyz="1 0 0" />
    <limit
      lower="-0.2"
      upper="0.2"
      effort="300"
      velocity="101.57816247" />
    <dynamics damping="0.0" friction="0.00" />
  </joint>

  <gazebo reference="leg_l1_link">
    <mu1>0.6</mu1>
    <mu2>0.6</mu2>
    <self_collide>1</self_collide>
  </gazebo>
  <gazebo reference="leg_l2_link">
    <mu1>0.6</mu1>
    <mu2>0.6</mu2>
    <self_collide>1</self_collide>
  </gazebo>
  <gazebo reference="leg_l3_link">
    <mu1>0.6</mu1>
    <mu2>0.6</mu2>
    <self_collide>1</self_collide>
  </gazebo>
  <gazebo reference="leg_l4_link">
    <mu1>0.6</mu1>
    <mu2>0.6</mu2>
    <self_collide>1</self_collide>
  </gazebo>
  <gazebo reference="leg_l5_link">
    <mu1>1.6</mu1>
    <mu2>1.6</mu2>
    <self_collide>0</self_collide>
    <kp value="1000000.0" />
    <kd value="100.0" />
    <maxVel>1.0</maxVel>
    <minDepth>0.00</minDepth>
  </gazebo>
  <gazebo reference="leg_l6_link">
    <mu1>1.6</mu1>
    <mu2>1.6</mu2>
    <self_collide>0</self_collide>
    <kp value="1000000.0" />
    <kd value="100.0" />
    <maxVel>1.0</maxVel>
    <minDepth>0.00</minDepth>
  </gazebo>

  <transmission name="leg_l1_tran">
    <type>transmission_interface/SimpleTransmission</type>
    <joint name="leg_l1_joint">
      <hardwareInterface>hardware_interface/EffortJointInterface</hardwareInterface>
    </joint>
    <actuator name="leg_l1_motor">
      <hardwareInterface>hardware_interface/EffortJointInterface</hardwareInterface>
      <mechanicalReduction>101</mechanicalReduction>
      <maxVelocity>4.188790205</maxVelocity> <!-- 40rpm -->
      <maxEffort>300.0</maxEffort>
    </actuator>
  </transmission>
  <transmission name="leg_l2_tran">
    <type>transmission_interface/SimpleTransmission</type>
    <joint name="leg_l2_joint">
      <hardwareInterface>hardware_interface/EffortJointInterface</hardwareInterface>
    </joint>
    <actuator name="leg_l2_motor">
      <hardwareInterface>hardware_interface/EffortJointInterface</hardwareInterface>
      <mechanicalReduction>101</mechanicalReduction>
      <maxVelocity>4.188790205</maxVelocity> <!-- 40rpm -->
      <maxEffort>300.0</maxEffort>
    </actuator>
  </transmission>
  <transmission name="leg_l3_tran">
    <type>transmission_interface/SimpleTransmission</type>
    <joint name="leg_l3_joint">
      <hardwareInterface>hardware_interface/EffortJointInterface</hardwareInterface>
    </joint>
    <actuator name="leg_l3_motor">
      <hardwareInterface>hardware_interface/EffortJointInterface</hardwareInterface>
      <mechanicalReduction>51</mechanicalReduction>
      <maxVelocity>5.759586532</maxVelocity>  <!-- 55rpm -->
      <maxEffort>300.0</maxEffort>
    </actuator>
  </transmission>
  <transmission name="leg_l4_tran">
    <type>transmission_interface/SimpleTransmission</type>
    <joint name="leg_l4_joint">
      <hardwareInterface>hardware_interface/EffortJointInterface</hardwareInterface>
    </joint>
    <actuator name="leg_l4_motor">
      <hardwareInterface>hardware_interface/EffortJointInterface</hardwareInterface>
      <mechanicalReduction>51</mechanicalReduction>
      <maxVelocity>5.759586532</maxVelocity> <!-- 55rpm -->
      <maxEffort>300.0</maxEffort>
    </actuator>
  </transmission>
  <transmission name="leg_l5_tran">
    <type>transmission_interface/SimpleTransmission</type>
    <joint name="leg_l5_joint">
      <hardwareInterface>hardware_interface/EffortJointInterface</hardwareInterface>
    </joint>
    <actuator name="leg_l5_motor">
      <hardwareInterface>hardware_interface/EffortJointInterface</hardwareInterface>
      <mechanicalReduction>51</mechanicalReduction>
      <maxVelocity>8.58701992</maxVelocity> <!-- 82rpm -->
      <maxEffort>300.0</maxEffort>
    </actuator>
  </transmission>
  <transmission name="leg_l6_tran">
    <type>transmission_interface/SimpleTransmission</type>
    <joint name="leg_l6_joint">
      <hardwareInterface>hardware_interface/EffortJointInterface</hardwareInterface>
    </joint>
    <actuator name="leg_l6_motor">
      <hardwareInterface>hardware_interface/EffortJointInterface</hardwareInterface>
      <mechanicalReduction>51</mechanicalReduction>
      <maxVelocity>10.157816247</maxVelocity> <!-- 97rpm -->
      <maxEffort>300.6</maxEffort>
    </actuator>
  </transmission>


  <link
    name="leg_r1_link">
    <inertial>
      <origin
        xyz="-0.088 0.00 -0.076"
        rpy="0 0 0" />
      <mass
        value="1.679" />
      <inertia
        ixx="0.002"
        ixy="0"
        ixz="0.001"
        iyy="0.003"
        iyz="0"
        izz="0.002" />
    </inertial>
    <visual>
      <origin
        xyz="0 0 0"
        rpy="0 0 0" />
      <geometry>
        <mesh
          filename="package://legged_ti5_description/meshes/R_HIP_Y_S.STL" />
      </geometry>
      <material
        name="">
        <color
          rgba="0.898039215686275 0.917647058823529 0.929411764705882 1" />
      </material>
    </visual>
    <!-- <collision>
      <origin
        xyz="0 0 0"
        rpy="0 0 0" />
      <geometry>
        <mesh
          filename="package://legged_ti5_description/meshes/R_HIP_Y_S.STL" />
      </geometry>
    </collision> -->
  </link>
  <joint
    name="leg_r1_joint"
    type="revolute">
    <origin
      xyz="0.1067 -0.105 0"
      rpy="0 0 0" />
    <parent
      link="base_link" />
    <child
      link="leg_r1_link" />
    <axis
      xyz="0 0 1" />
    <limit
      lower="-0.523"
      upper="0.523"
      effort="300"
      velocity="41.88790205" />
    <dynamics damping="0.0" friction="0.00" />
  </joint>
  <link
    name="leg_r2_link">
    <inertial>
      <origin
       xyz="0.071 -0.009 0.000"
        rpy="0 0 0" />
      <mass
        value="3.287" />
      <inertia
        ixx="0.006"
        ixy="0.000"
        ixz="0.000"
        iyy="0.006"
        iyz="0.000"
        izz="0.006" />
    </inertial>
    <visual>
      <origin
        xyz="0 0 0"
        rpy="0 0 0" />
      <geometry>
        <mesh
          filename="package://legged_ti5_description/meshes/R_HIP_R_S.STL" />
      </geometry>
      <material
        name="">
        <color
          rgba="0.898039215686275 0.917647058823529 0.929411764705882 1" />
      </material>
    </visual>
    <!-- <collision>
      <origin
        xyz="0 0 0"
        rpy="0 0 0" />
      <geometry>
        <mesh
          filename="package://legged_ti5_description/meshes/R_HIP_R_S.STL" />
      </geometry>
    </collision> -->
  </link>
  <joint
    name="leg_r2_joint"
    type="revolute">
    <origin
      xyz="-0.074 0 -0.09"
      rpy="0 0 0" />
    <parent
      link="leg_r1_link" />
    <child
      link="leg_r2_link" />
    <axis
      xyz="1 0 0" />
    <limit
      lower="-0.174"
      upper="0.174"
      effort="300"
      velocity="41.88790205" />
    <dynamics damping="0.0" friction="0.00" />
  </joint>
  <link
    name="leg_r3_link">
    <inertial>
      <origin
        xyz="0.008 -0.064 -0.184"
        rpy="0 0 0" />
      <mass
        value="6.432" />
      <inertia
        ixx="0.081"
        ixy="0.000"
        ixz="-0.001"
        iyy="0.082"
        iyz="-0.001"
        izz="0.015" />
    </inertial>
    <visual>
      <origin
        xyz="0 0 0"
        rpy="0 0 0" />
      <geometry>
        <mesh
          filename="package://legged_ti5_description/meshes/R_HIP_P_S.STL" />
      </geometry>
      <material
        name="">
        <color
          rgba="0.898039215686275 0.917647058823529 0.929411764705882 1" />
      </material>
    </visual>
    <!-- <collision>
      <origin
        xyz="0.01 -0.06 -0.185"
        rpy="0 0 0" />
      <geometry>
        <box size="0.12 0.12 0.30" />
        <mesh
          filename="package://legged_ti5_description/meshes/R_HIP_P_S.STL" />
      </geometry>
    </collision> -->
  </link>
  <joint
    name="leg_r3_joint"
    type="revolute">
    <origin
      xyz="0.074 0.0252 0"
      rpy="0 0 0" />
    <parent
      link="leg_r2_link" />
    <child
      link="leg_r3_link" />
    <axis
      xyz="0 1 0" />
    <limit
      lower="-0.785"
      upper="0.785"
      effort="300"
      velocity="57.59586532" />
    <dynamics damping="0.0" friction="0.00" />
  </joint>
  <link
    name="leg_r4_link">
    <inertial>
      <origin
        xyz="-0.000 -0.053 -0.179"
        rpy="0 0 0" />
      <mass
        value="3.222" />
      <inertia
        ixx="0.044"
        ixy="0.000"
        ixz="0.000"
        iyy="0.044"
        iyz="0.002"
        izz="0.003" />
    </inertial>
    <visual>
      <origin
        xyz="0 0 0"
        rpy="0 0 0" />
      <geometry>
        <mesh
          filename="package://legged_ti5_description/meshes/R_KNEE_P_S.STL" />
      </geometry>
      <material
        name="">
        <color
          rgba="0.898039215686275 0.917647058823529 0.929411764705882 1" />
      </material>
    </visual>
    <!-- <collision>
       <origin
        xyz="0 -0.05 -0.11"
        rpy="0 0 0" />
      <geometry>
        <box size="0.1 0.1 0.30" />
        <mesh
          filename="package://legged_ti5_description/meshes/R_KNEE_P_S.STL" />
      </geometry>
    </collision> -->
  </link>
  <joint
    name="leg_r4_joint"
    type="revolute">
    <origin
      xyz="0 0.0229 -0.42"
      rpy="0 0 0" />
    <parent
      link="leg_r3_link" />
    <child
      link="leg_r4_link" />
    <axis
      xyz="0 1 0" />
    <limit
      lower="-0"
      upper="2.09"
      effort="300"
     velocity="57.59586532" />
    <dynamics damping="0.0" friction="0.00" />
  </joint>
  <link
    name="leg_r5_link">
    <inertial>
      <origin
        xyz="0.008 0.046 0.0000"
        rpy="0 0 0" />
      <mass
        value="0.629" />
      <inertia
        ixx="0.00023285"
        ixy="0"
        ixz="0"
        iyy="0.00029849"
        iyz="0"
        izz="0.00028791" />
    </inertial>
    <visual>
      <origin
        xyz="0 0 0"
        rpy="0 0 0" />
      <geometry>
        <mesh
          filename="package://legged_ti5_description/meshes/R_ANKLE_P_S.STL" />
      </geometry>
      <material
        name="">
        <color
          rgba="0.647058823529412 0.619607843137255 0.588235294117647 1" />
      </material>
    </visual>
    <!-- <collision>
      <origin
        xyz="0 0 0"
        rpy="0 0 0" />
      <geometry>
        <mesh
          filename="package://legged_ti5_description/meshes/R_ANKLE_P_S.STL" />
      </geometry>
    </collision> -->
  </link>
  <joint
    name="leg_r5_joint"
    type="revolute">
    <origin
      xyz="0 -0.0938 -0.37"
      rpy="0 0 0" />
    <parent
      link="leg_r4_link" />
    <child
      link="leg_r5_link" />
    <axis
      xyz="0 1 0" />
    <limit
      lower="-2"
      upper="2"
      effort="300"
      velocity="85.8701992" />
    <dynamics damping="0.0" friction="0.00" />
  </joint>
  <link
    name="leg_r6_link">
    <inertial>
      <origin
        xyz="0.007 0.002 -0.068"
        rpy="0 0 0" />
      <mass
        value="0.802" />
      <inertia
        ixx="0.001"
        ixy="0"
        ixz="0"
        iyy="0.003"
        iyz="0"
        izz="0.003" />
    </inertial>
    <visual>
      <origin
        xyz="0 0 0"
        rpy="0 0 0" />
      <geometry>
        <mesh
          filename="package://legged_ti5_description/meshes/R_ANKLE_R_S.STL" />
      </geometry>
      <material
        name="">
        <color
          rgba="0.898039215686275 0.917647058823529 0.929411764705882 1" />
      </material>
    </visual>
    <collision>
          <!-- <origin
        xyz="-0.0 -0.00  -0.0715"
        rpy="0 0 0" /> -->
      <origin
        xyz="-0.0 -0.00  0.0"
        rpy="0 0 0" />
      <geometry>
        <mesh
          filename="package://legged_ti5_description/meshes/R_ANKLE_R_S.STL" />
      </geometry>
            <!-- <geometry>
        <box size="0.215 0.084 0.017" />
      </geometry> -->
    </collision>
  </link>
  <joint
    name="leg_r6_joint"
    type="revolute">
    <origin
      xyz="0.0251 0.0457 0"
      rpy="0 0 0" />
    <parent
      link="leg_r5_link" />
    <child
      link="leg_r6_link" />
    <axis
      xyz="1 0 0" />
    <limit
      lower="-0.2"
      upper="0.2"
      effort="300.6"
      velocity="101.57816247" />
    <dynamics damping="0.0" friction="0.00" />
  </joint>

  <gazebo reference="leg_r1_link">
    <mu1>0.6</mu1>
    <mu2>0.6</mu2>
    <self_collide>1</self_collide>
  </gazebo>
  <gazebo reference="leg_r2_link">
    <mu1>0.6</mu1>
    <mu2>0.6</mu2>
    <self_collide>1</self_collide>
  </gazebo>
  <gazebo reference="leg_r3_link">
    <mu1>0.6</mu1>
    <mu2>0.6</mu2>
    <self_collide>1</self_collide>
  </gazebo>
  <gazebo reference="leg_r4_link">
    <mu1>0.6</mu1>
    <mu2>0.6</mu2>
    <self_collide>1</self_collide>
  </gazebo>
  <gazebo reference="leg_r5_link">
    <mu1>1.6</mu1>
    <mu2>1.6</mu2>
    <self_collide>0</self_collide>
    <kp value="1000000.0" />
    <kd value="100.0" />
    <maxVel>1.0</maxVel>
    <minDepth>0.00</minDepth>
  </gazebo>
  <gazebo reference="leg_r6_link">
    <mu1>1.6</mu1>
    <mu2>1.6</mu2>
    <self_collide>0</self_collide>
    <kp value="1000000.0" />
    <kd value="100.0" />
    <maxVel>1.0</maxVel>
    <minDepth>0.00</minDepth>
  </gazebo>

  <transmission name="leg_r1_tran">
    <type>transmission_interface/SimpleTransmission</type>
    <joint name="leg_r1_joint">
      <hardwareInterface>hardware_interface/EffortJointInterface</hardwareInterface>
    </joint>
    <actuator name="leg_r1_motor">
      <hardwareInterface>hardware_interface/EffortJointInterface</hardwareInterface>
      <mechanicalReduction>101</mechanicalReduction>
      <maxVelocity>4.188790205</maxVelocity> <!-- 40rpm -->
      <maxEffort>300.0</maxEffort>
    </actuator>
  </transmission>
  <transmission name="leg_r2_tran">
    <type>transmission_interface/SimpleTransmission</type>
    <joint name="leg_r2_joint">
      <hardwareInterface>hardware_interface/EffortJointInterface</hardwareInterface>
    </joint>
    <actuator name="leg_r2_motor">
      <hardwareInterface>hardware_interface/EffortJointInterface</hardwareInterface>
      <mechanicalReduction>101</mechanicalReduction>
      <maxVelocity>4.188790205</maxVelocity> <!-- 40rpm -->
      <maxEffort>300.0</maxEffort>
    </actuator>
  </transmission>
  <transmission name="leg_r3_tran">
    <type>transmission_interface/SimpleTransmission</type>
    <joint name="leg_r3_joint">
      <hardwareInterface>hardware_interface/EffortJointInterface</hardwareInterface>
    </joint>
    <actuator name="leg_r3_motor">
      <hardwareInterface>hardware_interface/EffortJointInterface</hardwareInterface>
      <mechanicalReduction>51</mechanicalReduction>
      <maxVelocity>5.759586532</maxVelocity>  <!-- 55rpm -->
      <maxEffort>300.0</maxEffort>
    </actuator>
  </transmission>
  <transmission name="leg_r4_tran">
    <type>transmission_interface/SimpleTransmission</type>
    <joint name="leg_r4_joint">
      <hardwareInterface>hardware_interface/EffortJointInterface</hardwareInterface>
    </joint>
    <actuator name="leg_r4_motor">
      <hardwareInterface>hardware_interface/EffortJointInterface</hardwareInterface>
      <mechanicalReduction>51</mechanicalReduction>
      <maxVelocity>5.759586532</maxVelocity> <!-- 55rpm -->
      <maxEffort>300.0</maxEffort>
    </actuator>
  </transmission>
  <transmission name="leg_r5_tran">
    <type>transmission_interface/SimpleTransmission</type>
    <joint name="leg_r5_joint">
      <hardwareInterface>hardware_interface/EffortJointInterface</hardwareInterface>
    </joint>
    <actuator name="leg_r5_motor">
      <hardwareInterface>hardware_interface/EffortJointInterface</hardwareInterface>
      <mechanicalReduction>51</mechanicalReduction>
      <maxVelocity>8.58701992</maxVelocity> <!-- 82rpm -->
      <maxEffort>300.0</maxEffort>
    </actuator>
  </transmission>
  <transmission name="leg_r6_tran">
    <type>transmission_interface/SimpleTransmission</type>
    <joint name="leg_r6_joint">
      <hardwareInterface>hardware_interface/EffortJointInterface</hardwareInterface>
    </joint>
    <actuator name="leg_r6_motor">
      <hardwareInterface>hardware_interface/EffortJointInterface</hardwareInterface>
      <mechanicalReduction>51</mechanicalReduction>
      <maxVelocity>10.157816247</maxVelocity> <!-- 97rpm -->
      <maxEffort>8.6</maxEffort>
    </actuator>
  </transmission>


  <link
    name="WASITSWAY">
    <inertial>
      <origin
        xyz="0.0147146597548715 1.71251042402343E-07 0.00581657288948068"
        rpy="0 0 0" />
      <mass
        value="0.152814712624178" />
      <inertia
        ixx="0.000119834776210975"
        ixy="-1.75997200485822E-10"
        ixz="-2.87202905688535E-05"
        iyy="0.000158040219102489"
        iyz="3.22626963190764E-11"
        izz="0.000185996716004393" />
    </inertial>
    <visual>
      <origin
        xyz="0 0 0"
        rpy="0 0 0" />
      <geometry>
        <mesh
          filename="package://legged_ti5_description/meshes/WASITSWAY.STL" />
      </geometry>
      <material
        name="">
        <color
          rgba="0.898039215686275 0.917647058823529 0.929411764705882 1" />
      </material>
    </visual>
    <collision>
      <origin
        xyz="0 0 0"
        rpy="0 0 0" />
      <geometry>
        <mesh
          filename="package://legged_ti5_description/meshes/WASITSWAY.STL" />
      </geometry>
    </collision>
  </link>
  <joint
    name="WASITSWAY_R"
    type="fixed"   >
    <origin
      xyz="0.045 0 0.065"
      rpy="0 0.1 0" />
    <parent
      link="base_link" />
    <child
      link="WASITSWAY" />
    <axis
      xyz="1 0 0" />
    <limit
      lower="-0.174"
      upper="0.174"
      effort="200"
      velocity="200" />
    <dynamics
      friction="0" />
  </joint>
  <link
    name="WASITTWIST">
    <inertial>
      <origin
        xyz="7.2187028313242E-08 0.0084630468039914 0.0305767027260458"
        rpy="0 0 0" />
      <mass
        value="0.130302688849964" />
      <inertia
        ixx="0.000148101643229653"
        ixy="-2.39187724540077E-10"
        ixz="-2.21543332099018E-11"
        iyy="0.000169136843548439"
        iyz="-3.29334283076447E-05"
        izz="0.000101820344389148" />
    </inertial>
    <visual>
      <origin
        xyz="0 0 0"
        rpy="0 0 0" />
      <geometry>
        <mesh
          filename="package://legged_ti5_description/meshes/WASITTWIST.STL" />
      </geometry>
      <material
        name="">
        <color
          rgba="0.898039215686275 0.917647058823529 0.929411764705882 1" />
      </material>
    </visual>
    <collision>
      <origin
        xyz="0 0 0"
        rpy="0 0 0" />
      <geometry>
        <mesh
          filename="package://legged_ti5_description/meshes/WASITTWIST.STL" />
      </geometry>
    </collision>
  </link>
  <joint
    name="WASITTWIST_Y"
    type="fixed"   >
    <origin
      xyz="0.047 0 0.0247"
      rpy="0 0 0" />
    <parent
      link="WASITSWAY" />
    <child
      link="WASITTWIST" />
    <axis
      xyz="0 0 1" />
    <limit
      lower="-0.523"
      upper="0.523"
      effort="200"
      velocity="200" />
    <dynamics
      friction="0" />
  </joint>
  <link
    name="WASITLIFT">
    <inertial>
      <origin
        xyz="-0.0122957335669868 -0.0373485066576479 0.189407741151368"
        rpy="0 0 0" />
      <mass
        value="1.80867710372535" />
      <inertia
        ixx="0.00543525990651723"
        ixy="-2.46840203856839E-06"
        ixz="-0.000117320522345032"
        iyy="0.00488398853163546"
        iyz="2.88958638314628E-05"
        izz="0.00258257574965863" />
    </inertial>
    <visual>
      <origin
        xyz="0 0 0"
        rpy="0 0 0" />
      <geometry>
        <mesh
          filename="package://legged_ti5_description/meshes/WASITLIFT.STL" />
      </geometry>
      <material
        name="">
        <color
          rgba="0.898039215686275 0.917647058823529 0.929411764705882 1" />
      </material>
    </visual>
    <collision>
      <origin
        xyz="0 0 0"
        rpy="0 0 0" />
      <geometry>
        <mesh
          filename="package://legged_ti5_description/meshes/WASITLIFT.STL" />
      </geometry>
    </collision>
  </link>
  <joint
    name="WASITLIFT_P"
    type="fixed"  >
    <origin
      xyz="0 0.037277 0.0623"
      rpy="0 0 0" />
    <parent
      link="WASITTWIST" />
    <child
      link="WASITLIFT" />
    <axis
      xyz="0 1 0" />
    <limit
      lower="0"
      upper="0.524"
      effort="200"
      velocity="200" />
    <dynamics
      friction="0" />
  </joint>
  <link
    name="L_SHOUDLERLIFT">
    <inertial>
      <origin
        xyz="0.00490598651524514 0.0412219490647943 6.40882252533892E-06"
        rpy="0 0 0" />
      <mass
        value="0.153539578637761" />
      <inertia
        ixx="0.000148312860680509"
        ixy="-1.65250675152679E-05"
        ixz="5.7399033962826E-09"
        iyy="0.000101919470755931"
        iyz="5.42321011835387E-09"
        izz="0.000121371984027428" />
    </inertial>
    <visual>
      <origin
        xyz="0 0 0"
        rpy="0 0 0" />
      <geometry>
        <mesh
          filename="package://legged_ti5_description/meshes/L_SHOUDLERLIFT.STL" />
      </geometry>
      <material
        name="">
        <color
          rgba="0.898039215686275 0.917647058823529 0.929411764705882 1" />
      </material>
    </visual>
    <collision>
      <origin
        xyz="0 0 0"
        rpy="0 0 0" />
      <geometry>
        <mesh
          filename="package://legged_ti5_description/meshes/L_SHOUDLERLIFT.STL" />
      </geometry>
    </collision>
  </link>
  <joint
    name="L_SHOUDLERLIFT_P"
    type="fixed" >
    <origin
      xyz="0 0.057223 0.262"
      rpy="0 0 0" />
    <parent
      link="WASITLIFT" />
    <child
      link="L_SHOUDLERLIFT" />
    <axis
      xyz="0 1 0" />
    <limit
      lower="-2.09"
      upper="0.087"
      effort="200"
      velocity="200" />
    <dynamics
      friction="0" />
  </joint>
  <link
    name="L_SHOUDLERSWAY">
    <inertial>
      <origin
        xyz="-0.0340203958683601 0.00793166965519942 -0.0566176156881638"
        rpy="0 0 0" />
      <mass
        value="0.219297746770153" />
      <inertia
        ixx="0.000260584838503244"
        ixy="6.36781215192471E-06"
        ixz="-4.54364092885071E-05"
        iyy="0.000266182193797573"
        iyz="1.25736265419136E-05"
        izz="0.000178181155982569" />
    </inertial>
    <visual>
      <origin
        xyz="0 0 0"
        rpy="0 0 0" />
      <geometry>
        <mesh
          filename="package://legged_ti5_description/meshes/L_SHOUDLERSWAY.STL" />
      </geometry>
      <material
        name="">
        <color
          rgba="0.898039215686275 0.917647058823529 0.929411764705882 1" />
      </material>
    </visual>
    <collision>
      <origin
        xyz="0 0 0"
        rpy="0 0 0" />
      <geometry>
        <mesh
          filename="package://legged_ti5_description/meshes/L_SHOUDLERSWAY.STL" />
      </geometry>
    </collision>
  </link>
  <joint
    name="L_SHOUDLERSWAY_R"
    type="fixed" >
    <origin
      xyz="0.035 0.0765 0"
      rpy="0 0 0" />
    <parent
      link="L_SHOUDLERLIFT" />
    <child
      link="L_SHOUDLERSWAY" />
    <axis
      xyz="1 0 0" />
    <limit
      lower="0"
      upper="2.8"
      effort="200"
      velocity="200" />
    <dynamics
      friction="0" />
  </joint>
  <link
    name="L_FOREARM">
    <inertial>
      <origin
        xyz="-1.13085261460588E-07 0.00507723135581073 -0.0748516154215027"
        rpy="0 0 0" />
      <mass
        value="0.107848316769469" />
      <inertia
        ixx="0.000149891430835669"
        ixy="-6.66522637472604E-10"
        ixz="2.02296133341481E-10"
        iyy="0.000158652071171994"
        iyz="2.15039038111242E-05"
        izz="4.53131861969904E-05" />
    </inertial>
    <visual>
      <origin
        xyz="0 0 0"
        rpy="0 0 0" />
      <geometry>
        <mesh
          filename="package://legged_ti5_description/meshes/L_FOREARM.STL" />
      </geometry>
      <material
        name="">
        <color
          rgba="0.898039215686275 0.917647058823529 0.929411764705882 1" />
      </material>
    </visual>
    <collision>
      <origin
        xyz="0 0 0"
        rpy="0 0 0" />
      <geometry>
        <mesh
          filename="package://legged_ti5_description/meshes/L_FOREARM.STL" />
      </geometry>
    </collision>
  </link>
  <joint
    name="L_FOREARM_Y"
    type="fixed" >
    <origin
      xyz="-0.035 0.017911 -0.12785"
      rpy="0.13919 0.00082916 -0.0059186" />
    <parent
      link="L_SHOUDLERSWAY" />
    <child
      link="L_FOREARM" />
    <axis
      xyz="0 0 1" />
    <limit
      lower="-1.57"
      upper="1.57"
      effort="200"
      velocity="200" />
    <dynamics
      friction="0" />
  </joint>
  <link
    name="L_ELBOW">
    <inertial>
      <origin
        xyz="-0.00201243110528096 -0.0112213690198411 -0.144630402145828"
        rpy="0 0 0" />
      <mass
        value="0.321196616487929" />
      <inertia
        ixx="0.000609935199310167"
        ixy="-1.45613726831185E-06"
        ixz="2.89953338581087E-06"
        iyy="0.00058833962553486"
        iyz="6.46665233059303E-05"
        izz="0.000153722524270823" />
    </inertial>
    <visual>
      <origin
        xyz="0 0 0"
        rpy="0 0 0" />
      <geometry>
        <mesh
          filename="package://legged_ti5_description/meshes/L_ELBOW.STL" />
      </geometry>
      <material
        name="">
        <color
          rgba="0.898039215686275 0.917647058823529 0.929411764705882 1" />
      </material>
    </visual>
    <collision>
      <origin
        xyz="0 0 0"
        rpy="0 0 0" />
      <geometry>
        <mesh
          filename="package://legged_ti5_description/meshes/L_ELBOW.STL" />
      </geometry>
    </collision>
  </link>
  <joint
    name="L_ELBOW_P"
    type="fixed" >
    <origin
      xyz="0 0.0305 -0.1209"
      rpy="0 0 0" />
    <parent
      link="L_FOREARM" />
    <child
      link="L_ELBOW" />
    <axis
      xyz="0 1 0" />
    <limit
      lower="-1.57"
      upper="0"
      effort="200"
      velocity="200" />
    <dynamics
      friction="0" />
  </joint>
  <link
    name="R_SHOUDLERLIFT">
    <inertial>
      <origin
        xyz="0.0049059860372935 -0.0412219490647961 -6.40932149720275E-06"
        rpy="0 0 0" />
      <mass
        value="0.153539578637762" />
      <inertia
        ixx="0.000148312860957692"
        ixy="1.65250662408567E-05"
        ixz="-5.7399026084721E-09"
        iyy="0.000101919470755932"
        iyz="5.42204175083918E-09"
        izz="0.000121371983750243" />
    </inertial>
    <visual>
      <origin
        xyz="0 0 0"
        rpy="0 0 0" />
      <geometry>
        <mesh
          filename="package://legged_ti5_description/meshes/R_SHOUDLERLIFT.STL" />
      </geometry>
      <material
        name="">
        <color
          rgba="0.898039215686275 0.917647058823529 0.929411764705882 1" />
      </material>
    </visual>
    <collision>
      <origin
        xyz="0 0 0"
        rpy="0 0 0" />
      <geometry>
        <mesh
          filename="package://legged_ti5_description/meshes/R_SHOUDLERLIFT.STL" />
      </geometry>
    </collision>
  </link>
  <joint
    name="R_SHOUDLERLIFT_P"
    type="fixed"  >
    <origin
      xyz="0 -0.13178 0.262"
      rpy="0 0 0" />
    <parent
      link="WASITLIFT" />
    <child
      link="R_SHOUDLERLIFT" />
    <axis
      xyz="0 1 0" />
    <limit
      lower="-0.087"
      upper="2.09"
      effort="200"
      velocity="200" />
    <dynamics
      friction="0" />
  </joint>
  <link
    name="R_SHOUDLERSWAY">
    <inertial>
      <origin
        xyz="-0.0340205169183369 -0.00920486477491345 -0.0564245873686476"
        rpy="0 0 0" />
      <mass
        value="0.219297182857429" />
      <inertia
        ixx="0.000260587299778567"
        ixy="-7.38289139770258E-06"
        ixz="-4.52832706580432E-05"
        iyy="0.000265571647387341"
        iyz="-1.45435982818493E-05"
        izz="0.000178793056139537" />
    </inertial>
    <visual>
      <origin
        xyz="0 0 0"
        rpy="0 0 0" />
      <geometry>
        <mesh
          filename="package://legged_ti5_description/meshes/R_SHOUDLERSWAY.STL" />
      </geometry>
      <material
        name="">
        <color
          rgba="0.898039215686275 0.917647058823529 0.929411764705882 1" />
      </material>
    </visual>
    <collision>
      <origin
        xyz="0 0 0"
        rpy="0 0 0" />
      <geometry>
        <mesh
          filename="package://legged_ti5_description/meshes/R_SHOUDLERSWAY.STL" />
      </geometry>
    </collision>
  </link>
  <joint
    name="R_SHOUDLERSWAY_R"
    type="fixed" >
    <origin
      xyz="0.035 -0.0765 0"
      rpy="0 0 0" />
    <parent
      link="R_SHOUDLERLIFT" />
    <child
      link="R_SHOUDLERSWAY" />
    <axis
      xyz="1 0 0" />
    <limit
      lower="-2.8"
      upper="0"
      effort="200"
      velocity="200" />
    <dynamics
      friction="0" />
  </joint>
  <link
    name="R_FOREARM">
    <inertial>
      <origin
        xyz="1.11681443565326E-07 -0.00507723982818037 -0.0748516234321389"
        rpy="0 0 0" />
      <mass
        value="0.10784827045776" />
      <inertia
        ixx="0.000149891390975243"
        ixy="-6.60606420722941E-10"
        ixz="-2.08082256587301E-10"
        iyy="0.000158652062987143"
        iyz="-2.15038870076046E-05"
        izz="4.53131716934871E-05" />
    </inertial>
    <visual>
      <origin
        xyz="0 0 0"
        rpy="0 0 0" />
      <geometry>
        <mesh
          filename="package://legged_ti5_description/meshes/R_FOREARM.STL" />
      </geometry>
      <material
        name="">
        <color
          rgba="0.898039215686275 0.917647058823529 0.929411764705882 1" />
      </material>
    </visual>
    <collision>
      <origin
        xyz="0 0 0"
        rpy="0 0 0" />
      <geometry>
        <mesh
          filename="package://legged_ti5_description/meshes/R_FOREARM.STL" />
      </geometry>
    </collision>
  </link>
  <joint
    name="R_FOREARM_Y"
    type="fixed"  >
    <origin
      xyz="-0.035 -0.020785 -0.12742"
      rpy="-0.1617 0.0011622 0.0071247" />
    <parent
      link="R_SHOUDLERSWAY" />
    <child
      link="R_FOREARM" />
    <axis
      xyz="0 0 1" />
    <limit
      lower="-1.57"
      upper="1.57"
      effort="200"
      velocity="200" />
    <dynamics
      friction="0" />
  </joint>
  <link
    name="R_ELBOW">
    <inertial>
      <origin
        xyz="0.00229247235603046 0.000699544566957672 -0.144569979710919"
        rpy="0 0 0" />
      <mass
        value="0.321197384960619" />
      <inertia
        ixx="0.000609508841046388"
        ixy="3.34431926307859E-06"
        ixz="1.65315293689578E-05"
        iyy="0.00058833837413993"
        iyz="-6.45673585827914E-05"
        izz="0.000154150375024939" />
    </inertial>
    <visual>
      <origin
        xyz="0 0 0"
        rpy="0 0 0" />
      <geometry>
        <mesh
          filename="package://legged_ti5_description/meshes/R_ELBOW.STL" />
      </geometry>
      <material
        name="">
        <color
          rgba="0.898039215686275 0.917647058823529 0.929411764705882 1" />
      </material>
    </visual>
    <collision>
      <origin
        xyz="0 0 0"
        rpy="0 0 0" />
      <geometry>
        <mesh
          filename="package://legged_ti5_description/meshes/R_ELBOW.STL" />
      </geometry>
    </collision>
  </link>
  <joint
    name="R_ELBOW_P"
    type="fixed" >
    <origin
      xyz="0 -0.0205 -0.1209"
      rpy="0 0 0" />
    <parent
      link="R_FOREARM" />
    <child
      link="R_ELBOW" />
    <axis
      xyz="0 1 0" />
    <limit
      lower="0"
      upper="1.57"
      effort="200"
      velocity="200" />
    <dynamics
      friction="0" />
  </joint>
</robot>